2019-03-16 10:41:25,753 INFO: Microblog startup [in C:\Users\Maciek\PycharmProjects\app\__init__.py:27]
2019-03-16 10:42:30,646 ERROR: Exception on /edit_profile [POST] [in c:\users\maciek\anaconda3\envs\webdev\lib\site-packages\flask\app.py:1761]
Traceback (most recent call last):
  File "c:\users\maciek\anaconda3\envs\webdev\lib\site-packages\sqlalchemy\engine\base.py", line 1236, in _execute_context
    cursor, statement, parameters, context
  File "c:\users\maciek\anaconda3\envs\webdev\lib\site-packages\sqlalchemy\engine\default.py", line 536, in do_execute
    cursor.execute(statement, parameters)
sqlite3.IntegrityError: UNIQUE constraint failed: user.username

The above exception was the direct cause of the following exception:

Traceback (most recent call last):
  File "c:\users\maciek\anaconda3\envs\webdev\lib\site-packages\flask\app.py", line 2292, in wsgi_app
    response = self.full_dispatch_request()
  File "c:\users\maciek\anaconda3\envs\webdev\lib\site-packages\flask\app.py", line 1815, in full_dispatch_request
    rv = self.handle_user_exception(e)
  File "c:\users\maciek\anaconda3\envs\webdev\lib\site-packages\flask\app.py", line 1718, in handle_user_exception
    reraise(exc_type, exc_value, tb)
  File "c:\users\maciek\anaconda3\envs\webdev\lib\site-packages\flask\_compat.py", line 35, in reraise
    raise value
  File "c:\users\maciek\anaconda3\envs\webdev\lib\site-packages\flask\app.py", line 1813, in full_dispatch_request
    rv = self.dispatch_request()
  File "c:\users\maciek\anaconda3\envs\webdev\lib\site-packages\flask\app.py", line 1799, in dispatch_request
    return self.view_functions[rule.endpoint](**req.view_args)
  File "c:\users\maciek\anaconda3\envs\webdev\lib\site-packages\flask_login\utils.py", line 261, in decorated_view
    return func(*args, **kwargs)
  File "C:\Users\Maciek\PycharmProjects\app\routes.py", line 85, in edit_profile
    db.session.commit()
  File "c:\users\maciek\anaconda3\envs\webdev\lib\site-packages\sqlalchemy\orm\scoping.py", line 162, in do
    return getattr(self.registry(), name)(*args, **kwargs)
  File "c:\users\maciek\anaconda3\envs\webdev\lib\site-packages\sqlalchemy\orm\session.py", line 1023, in commit
    self.transaction.commit()
  File "c:\users\maciek\anaconda3\envs\webdev\lib\site-packages\sqlalchemy\orm\session.py", line 487, in commit
    self._prepare_impl()
  File "c:\users\maciek\anaconda3\envs\webdev\lib\site-packages\sqlalchemy\orm\session.py", line 466, in _prepare_impl
    self.session.flush()
  File "c:\users\maciek\anaconda3\envs\webdev\lib\site-packages\sqlalchemy\orm\session.py", line 2446, in flush
    self._flush(objects)
  File "c:\users\maciek\anaconda3\envs\webdev\lib\site-packages\sqlalchemy\orm\session.py", line 2584, in _flush
    transaction.rollback(_capture_exception=True)
  File "c:\users\maciek\anaconda3\envs\webdev\lib\site-packages\sqlalchemy\util\langhelpers.py", line 67, in __exit__
    compat.reraise(exc_type, exc_value, exc_tb)
  File "c:\users\maciek\anaconda3\envs\webdev\lib\site-packages\sqlalchemy\util\compat.py", line 277, in reraise
    raise value
  File "c:\users\maciek\anaconda3\envs\webdev\lib\site-packages\sqlalchemy\orm\session.py", line 2544, in _flush
    flush_context.execute()
  File "c:\users\maciek\anaconda3\envs\webdev\lib\site-packages\sqlalchemy\orm\unitofwork.py", line 416, in execute
    rec.execute(self)
  File "c:\users\maciek\anaconda3\envs\webdev\lib\site-packages\sqlalchemy\orm\unitofwork.py", line 583, in execute
    uow,
  File "c:\users\maciek\anaconda3\envs\webdev\lib\site-packages\sqlalchemy\orm\persistence.py", line 236, in save_obj
    update,
  File "c:\users\maciek\anaconda3\envs\webdev\lib\site-packages\sqlalchemy\orm\persistence.py", line 976, in _emit_update_statements
    statement, multiparams
  File "c:\users\maciek\anaconda3\envs\webdev\lib\site-packages\sqlalchemy\engine\base.py", line 980, in execute
    return meth(self, multiparams, params)
  File "c:\users\maciek\anaconda3\envs\webdev\lib\site-packages\sqlalchemy\sql\elements.py", line 273, in _execute_on_connection
    return connection._execute_clauseelement(self, multiparams, params)
  File "c:\users\maciek\anaconda3\envs\webdev\lib\site-packages\sqlalchemy\engine\base.py", line 1099, in _execute_clauseelement
    distilled_params,
  File "c:\users\maciek\anaconda3\envs\webdev\lib\site-packages\sqlalchemy\engine\base.py", line 1240, in _execute_context
    e, statement, parameters, cursor, context
  File "c:\users\maciek\anaconda3\envs\webdev\lib\site-packages\sqlalchemy\engine\base.py", line 1458, in _handle_dbapi_exception
    util.raise_from_cause(sqlalchemy_exception, exc_info)
  File "c:\users\maciek\anaconda3\envs\webdev\lib\site-packages\sqlalchemy\util\compat.py", line 296, in raise_from_cause
    reraise(type(exception), exception, tb=exc_tb, cause=cause)
  File "c:\users\maciek\anaconda3\envs\webdev\lib\site-packages\sqlalchemy\util\compat.py", line 276, in reraise
    raise value.with_traceback(tb)
  File "c:\users\maciek\anaconda3\envs\webdev\lib\site-packages\sqlalchemy\engine\base.py", line 1236, in _execute_context
    cursor, statement, parameters, context
  File "c:\users\maciek\anaconda3\envs\webdev\lib\site-packages\sqlalchemy\engine\default.py", line 536, in do_execute
    cursor.execute(statement, parameters)
sqlalchemy.exc.IntegrityError: (sqlite3.IntegrityError) UNIQUE constraint failed: user.username [SQL: 'UPDATE user SET username=?, about_me=? WHERE user.id = ?'] [parameters: ('tarpalsus', 'Trying to make Flask work.', 2)] (Background on this error at: http://sqlalche.me/e/gkpj)
2019-03-16 10:47:15,316 INFO: Microblog startup [in C:\Users\Maciek\PycharmProjects\app\__init__.py:27]
2019-03-16 11:19:49,441 INFO: Microblog startup [in C:\Users\Maciek\PycharmProjects\app\__init__.py:27]
2019-03-16 11:19:59,293 INFO: Microblog startup [in C:\Users\Maciek\PycharmProjects\app\__init__.py:27]
2019-03-16 11:22:11,206 INFO: Microblog startup [in C:\Users\Maciek\PycharmProjects\app\__init__.py:27]
2019-03-16 11:22:32,265 INFO: Microblog startup [in C:\Users\Maciek\PycharmProjects\app\__init__.py:27]
2019-03-16 11:22:46,308 INFO: Microblog startup [in C:\Users\Maciek\PycharmProjects\app\__init__.py:27]
2019-03-16 12:01:28,172 INFO: Microblog startup [in C:\Users\Maciek\PycharmProjects\app\__init__.py:27]
2019-03-16 12:02:02,314 ERROR: Exception on /follow/username [GET] [in c:\users\maciek\anaconda3\envs\webdev\lib\site-packages\flask\app.py:1761]
Traceback (most recent call last):
  File "c:\users\maciek\anaconda3\envs\webdev\lib\site-packages\flask\app.py", line 2292, in wsgi_app
    response = self.full_dispatch_request()
  File "c:\users\maciek\anaconda3\envs\webdev\lib\site-packages\flask\app.py", line 1815, in full_dispatch_request
    rv = self.handle_user_exception(e)
  File "c:\users\maciek\anaconda3\envs\webdev\lib\site-packages\flask\app.py", line 1718, in handle_user_exception
    reraise(exc_type, exc_value, tb)
  File "c:\users\maciek\anaconda3\envs\webdev\lib\site-packages\flask\_compat.py", line 35, in reraise
    raise value
  File "c:\users\maciek\anaconda3\envs\webdev\lib\site-packages\flask\app.py", line 1813, in full_dispatch_request
    rv = self.dispatch_request()
  File "c:\users\maciek\anaconda3\envs\webdev\lib\site-packages\flask\app.py", line 1799, in dispatch_request
    return self.view_functions[rule.endpoint](**req.view_args)
  File "c:\users\maciek\anaconda3\envs\webdev\lib\site-packages\flask_login\utils.py", line 261, in decorated_view
    return func(*args, **kwargs)
TypeError: follow() missing 1 required positional argument: 'username'
2019-03-16 12:03:20,447 INFO: Microblog startup [in C:\Users\Maciek\PycharmProjects\app\__init__.py:27]
2019-03-16 12:51:28,643 INFO: Microblog startup [in C:\Users\Maciek\PycharmProjects\app\__init__.py:27]
2019-03-16 12:51:31,255 INFO: Microblog startup [in C:\Users\Maciek\PycharmProjects\app\__init__.py:27]
