2019-03-16 12:51:33,571 ERROR: Exception on /index [GET] [in c:\users\maciek\anaconda3\envs\webdev\lib\site-packages\flask\app.py:1761]
Traceback (most recent call last):
  File "c:\users\maciek\anaconda3\envs\webdev\lib\site-packages\flask\app.py", line 2292, in wsgi_app
    response = self.full_dispatch_request()
  File "c:\users\maciek\anaconda3\envs\webdev\lib\site-packages\flask\app.py", line 1815, in full_dispatch_request
    rv = self.handle_user_exception(e)
  File "c:\users\maciek\anaconda3\envs\webdev\lib\site-packages\flask\app.py", line 1718, in handle_user_exception
    reraise(exc_type, exc_value, tb)
  File "c:\users\maciek\anaconda3\envs\webdev\lib\site-packages\flask\_compat.py", line 35, in reraise
    raise value
  File "c:\users\maciek\anaconda3\envs\webdev\lib\site-packages\flask\app.py", line 1813, in full_dispatch_request
    rv = self.dispatch_request()
  File "c:\users\maciek\anaconda3\envs\webdev\lib\site-packages\flask\app.py", line 1799, in dispatch_request
    return self.view_functions[rule.endpoint](**req.view_args)
  File "c:\users\maciek\anaconda3\envs\webdev\lib\site-packages\flask_login\utils.py", line 261, in decorated_view
    return func(*args, **kwargs)
  File "C:\Users\Maciek\PycharmProjects\app\routes.py", line 33, in index
    return render_template('index.html', title='Home', posts=posts)
  File "c:\users\maciek\anaconda3\envs\webdev\lib\site-packages\flask\templating.py", line 135, in render_template
    context, ctx.app)
  File "c:\users\maciek\anaconda3\envs\webdev\lib\site-packages\flask\templating.py", line 117, in _render
    rv = template.render(context)
  File "c:\users\maciek\anaconda3\envs\webdev\lib\site-packages\jinja2\environment.py", line 1008, in render
    return self.environment.handle_exception(exc_info, True)
  File "c:\users\maciek\anaconda3\envs\webdev\lib\site-packages\jinja2\environment.py", line 780, in handle_exception
    reraise(exc_type, exc_value, tb)
  File "c:\users\maciek\anaconda3\envs\webdev\lib\site-packages\jinja2\_compat.py", line 37, in reraise
    raise value.with_traceback(tb)
  File "C:\Users\Maciek\PycharmProjects\app\templates\index.html", line 1, in top-level template code
    {% extends "base.html" %}
  File "C:\Users\Maciek\PycharmProjects\app\templates\base.html", line 31, in top-level template code
    {% block content %}{% endblock %}
  File "C:\Users\Maciek\PycharmProjects\app\templates\index.html", line 6, in block "content"
    {{ form.hidden_tag() }}
  File "c:\users\maciek\anaconda3\envs\webdev\lib\site-packages\jinja2\environment.py", line 430, in getattr
    return getattr(obj, attribute)
jinja2.exceptions.UndefinedError: 'form' is undefined
2019-03-16 12:52:32,133 INFO: Microblog startup [in C:\Users\Maciek\PycharmProjects\app\__init__.py:27]
2019-03-16 12:53:21,462 INFO: Microblog startup [in C:\Users\Maciek\PycharmProjects\app\__init__.py:27]
2019-03-16 12:53:27,978 ERROR: Exception on /index [GET] [in c:\users\maciek\anaconda3\envs\webdev\lib\site-packages\flask\app.py:1761]
Traceback (most recent call last):
  File "c:\users\maciek\anaconda3\envs\webdev\lib\site-packages\flask\app.py", line 2292, in wsgi_app
    response = self.full_dispatch_request()
  File "c:\users\maciek\anaconda3\envs\webdev\lib\site-packages\flask\app.py", line 1815, in full_dispatch_request
    rv = self.handle_user_exception(e)
  File "c:\users\maciek\anaconda3\envs\webdev\lib\site-packages\flask\app.py", line 1718, in handle_user_exception
    reraise(exc_type, exc_value, tb)
  File "c:\users\maciek\anaconda3\envs\webdev\lib\site-packages\flask\_compat.py", line 35, in reraise
    raise value
  File "c:\users\maciek\anaconda3\envs\webdev\lib\site-packages\flask\app.py", line 1813, in full_dispatch_request
    rv = self.dispatch_request()
  File "c:\users\maciek\anaconda3\envs\webdev\lib\site-packages\flask\app.py", line 1799, in dispatch_request
    return self.view_functions[rule.endpoint](**req.view_args)
  File "c:\users\maciek\anaconda3\envs\webdev\lib\site-packages\flask_login\utils.py", line 261, in decorated_view
    return func(*args, **kwargs)
  File "C:\Users\Maciek\PycharmProjects\app\routes.py", line 23, in index
    posts = current_user.followed_posts.all()
AttributeError: 'function' object has no attribute 'all'
2019-03-16 12:53:46,672 ERROR: Exception on /index [GET] [in c:\users\maciek\anaconda3\envs\webdev\lib\site-packages\flask\app.py:1761]
Traceback (most recent call last):
  File "c:\users\maciek\anaconda3\envs\webdev\lib\site-packages\flask\app.py", line 2292, in wsgi_app
    response = self.full_dispatch_request()
  File "c:\users\maciek\anaconda3\envs\webdev\lib\site-packages\flask\app.py", line 1815, in full_dispatch_request
    rv = self.handle_user_exception(e)
  File "c:\users\maciek\anaconda3\envs\webdev\lib\site-packages\flask\app.py", line 1718, in handle_user_exception
    reraise(exc_type, exc_value, tb)
  File "c:\users\maciek\anaconda3\envs\webdev\lib\site-packages\flask\_compat.py", line 35, in reraise
    raise value
  File "c:\users\maciek\anaconda3\envs\webdev\lib\site-packages\flask\app.py", line 1813, in full_dispatch_request
    rv = self.dispatch_request()
  File "c:\users\maciek\anaconda3\envs\webdev\lib\site-packages\flask\app.py", line 1799, in dispatch_request
    return self.view_functions[rule.endpoint](**req.view_args)
  File "c:\users\maciek\anaconda3\envs\webdev\lib\site-packages\flask_login\utils.py", line 261, in decorated_view
    return func(*args, **kwargs)
  File "C:\Users\Maciek\PycharmProjects\app\routes.py", line 23, in index
    posts = current_user.followed_posts().all()
AttributeError: 'function' object has no attribute 'all'
2019-03-16 12:53:55,962 INFO: Microblog startup [in C:\Users\Maciek\PycharmProjects\app\__init__.py:27]
2019-03-16 12:53:57,893 ERROR: Exception on /index [GET] [in c:\users\maciek\anaconda3\envs\webdev\lib\site-packages\flask\app.py:1761]
Traceback (most recent call last):
  File "c:\users\maciek\anaconda3\envs\webdev\lib\site-packages\flask\app.py", line 2292, in wsgi_app
    response = self.full_dispatch_request()
  File "c:\users\maciek\anaconda3\envs\webdev\lib\site-packages\flask\app.py", line 1815, in full_dispatch_request
    rv = self.handle_user_exception(e)
  File "c:\users\maciek\anaconda3\envs\webdev\lib\site-packages\flask\app.py", line 1718, in handle_user_exception
    reraise(exc_type, exc_value, tb)
  File "c:\users\maciek\anaconda3\envs\webdev\lib\site-packages\flask\_compat.py", line 35, in reraise
    raise value
  File "c:\users\maciek\anaconda3\envs\webdev\lib\site-packages\flask\app.py", line 1813, in full_dispatch_request
    rv = self.dispatch_request()
  File "c:\users\maciek\anaconda3\envs\webdev\lib\site-packages\flask\app.py", line 1799, in dispatch_request
    return self.view_functions[rule.endpoint](**req.view_args)
  File "c:\users\maciek\anaconda3\envs\webdev\lib\site-packages\flask_login\utils.py", line 261, in decorated_view
    return func(*args, **kwargs)
  File "C:\Users\Maciek\PycharmProjects\app\routes.py", line 23, in index
    posts = current_user.followed_posts().all()
  File "C:\Users\Maciek\PycharmProjects\app\models.py", line 53, in followed_posts
    own = Post.query_filter_by(user_id=self.id)
AttributeError: type object 'Post' has no attribute 'query_filter_by'
2019-03-16 12:54:00,106 ERROR: Exception on /index [GET] [in c:\users\maciek\anaconda3\envs\webdev\lib\site-packages\flask\app.py:1761]
Traceback (most recent call last):
  File "c:\users\maciek\anaconda3\envs\webdev\lib\site-packages\flask\app.py", line 2292, in wsgi_app
    response = self.full_dispatch_request()
  File "c:\users\maciek\anaconda3\envs\webdev\lib\site-packages\flask\app.py", line 1815, in full_dispatch_request
    rv = self.handle_user_exception(e)
  File "c:\users\maciek\anaconda3\envs\webdev\lib\site-packages\flask\app.py", line 1718, in handle_user_exception
    reraise(exc_type, exc_value, tb)
  File "c:\users\maciek\anaconda3\envs\webdev\lib\site-packages\flask\_compat.py", line 35, in reraise
    raise value
  File "c:\users\maciek\anaconda3\envs\webdev\lib\site-packages\flask\app.py", line 1813, in full_dispatch_request
    rv = self.dispatch_request()
  File "c:\users\maciek\anaconda3\envs\webdev\lib\site-packages\flask\app.py", line 1799, in dispatch_request
    return self.view_functions[rule.endpoint](**req.view_args)
  File "c:\users\maciek\anaconda3\envs\webdev\lib\site-packages\flask_login\utils.py", line 261, in decorated_view
    return func(*args, **kwargs)
  File "C:\Users\Maciek\PycharmProjects\app\routes.py", line 23, in index
    posts = current_user.followed_posts().all()
  File "C:\Users\Maciek\PycharmProjects\app\models.py", line 53, in followed_posts
    own = Post.query_filter_by(user_id=self.id)
AttributeError: type object 'Post' has no attribute 'query_filter_by'
2019-03-16 12:55:15,345 INFO: Microblog startup [in C:\Users\Maciek\PycharmProjects\app\__init__.py:27]
2019-03-16 13:01:55,493 INFO: Microblog startup [in C:\Users\Maciek\PycharmProjects\app\__init__.py:27]
2019-03-16 13:07:09,047 INFO: Microblog startup [in C:\Users\Maciek\PycharmProjects\app\__init__.py:27]
